Workbook

Sheet PRODUCT ENQUIRY
A1: PRODUCT ENQUIRY
B6: PLEASE ENTER YOUR PRODUCT REFERENCE CODE | C6: TO-JA-DE-NU-10
B8: Product: | C8: =IFERROR(VLOOKUP(C6,'REFERENCING & DATABASE'!$D$2:$K$131,2,FALSE),"Reference code does not exist") -> Denim Jacket
B9: Description: | C9: =IFERROR(VLOOKUP(C6,'REFERENCING & DATABASE'!$D$2:$K$131,3,FALSE),"Reference code does not exist") -> A timeless and versatile jacket that adds an edge to any outfit.
B10: Colour: | C10: =IFERROR(VLOOKUP(C6,'REFERENCING & DATABASE'!$D$2:$K$131,4,FALSE),"Reference code does not exist") -> Nude, Purple
B11: Size: | C11: =IFERROR(VLOOKUP(C6,'REFERENCING & DATABASE'!$D$2:$K$131,5,FALSE),"Reference code does not exist") -> 10
B12: Price: | C12: =IFERROR(VLOOKUP(C6,'REFERENCING & DATABASE'!$D$2:$K$131,6,FALSE),"Reference code does not exist") -> 45
B13: Available stock in store: | C13: =IFERROR(VLOOKUP($C$6,'STORE STK & SALES MGT'!$A2:$V514,9,FALSE)-VLOOKUP($C$6,'STORE STK & SALES MGT'!$A2:$V514,10,FALSE),"Reference code does not exist") -> 10
B14: Available stock in warehouse: | C14: =IFERROR(VLOOKUP(C6,'WHS STK MGT & ALLOC.'!$A$2:$K$105,9,FALSE),"Reference code does not exist") -> 90

Sheet REFERENCING & DATABASE
A1: REFERENCING & DATABASE
B4: TOTAL NO OF PRODUCTS
B5: =SUM(A7:A13) -> 2050
A6: NO OF PRODUCTS | B6: CATEGORY | C6: SUB-CATEGORY | D6: REFERENCE | E6: PRODUCT NAME | F6: DESCRIPTION | G6: COLOUR | H6: SIZE | I6: COST PRICE (€) | J6: MARGIN (%) | K6: RETAIL PRICE (€)
A7: 450 | B7: TOPS | C7: TEES | D7: =CONCATENATE(UPPER(LEFT(B7,1)&MID(B7,2,1)&"-"&LEFT(C7,1)&MID(C7,2,1)&"-"&LEFT(E7,1)&MID(E7,2,1)&"-"&LEFT(G7,1)&MID(G7,2,1)&"-"&LEFT(H7,1)&MID(H7,2,1))) -> TO-TE-CO-GR-58 | E7: Cozy Comfort Tee | F7: A relaxed-fit tee made from super-soft cotton, perfect for everyday wear. | G7: Grey,Black,Blue | H7: 58 | I7: 17 | J7: =ROUND((K7-I7)/I7*100,2) -> 105.88 | K7: 35
A8: 300 | B8: TOPS | C8: TEES | D8: =CONCATENATE(UPPER(LEFT(B8,1)&MID(B8,2,1)&"-"&LEFT(C8,1)&MID(C8,2,1)&"-"&LEFT(E8,1)&MID(E8,2,1)&"-"&LEFT(G8,1)&MID(G8,2,1)&"-"&LEFT(H8,1)&MID(H8,2,1))) -> TO-TE-GR-BL-58 | E8: Graphic Statement Tee | F8: A bold graphic tee that expresses your unique style. | G8: Blue,Black,White | H8: 58 | I8: 20 | J8: =ROUND((K8-I8)/I8*100,2) -> 100 | K8: 40
A9: 300 | B9: TOPS | C9: SHIRTS | D9: =CONCATENATE(UPPER(LEFT(B9,1)&MID(B9,2,1)&"-"&LEFT(C9,1)&MID(C9,2,1)&"-"&LEFT(E9,1)&MID(E9,2,1)&"-"&LEFT(G9,1)&MID(G9,2,1)&"-"&LEFT(H9,1)&MID(H9,2,1))) -> TO-SH-CL-PI-10 | E9: Classic Button-Down Shirt | F9: A timeless and versatile shirt for work or casual occasions. | G9: Pink, Brown,Yellow | H9: 10 | I9: 25 | J9: =ROUND((K9-I9)/I9*100,2) -> 60 | K9: 40
A10: 400 | B10: TOPS | C10: SHIRTS | D10: =CONCATENATE(UPPER(LEFT(B10,1)&MID(B10,2,1)&"-"&LEFT(C10,1)&MID(C10,2,1)&"-"&LEFT(E10,1)&MID(E10,2,1)&"-"&LEFT(G10,1)&MID(G10,2,1)&"-"&LEFT(H10,1)&MID(H10,2,1))) -> TO-SH-LI-PI-10 | E10: Linen Blend Shirt | F10: A lightweight and breathable shirt for warmer weather. | G10: Pink, Clear | H10: 10 | I10: 25 | J10: =ROUND((K10-I10)/I10*100,2) -> 100 | K10: 50
A11: 200 | B11: TOPS | C11: SWEATERS | D11: =CONCATENATE(UPPER(LEFT(B11,1)&MID(B11,2,1)&"-"&LEFT(C11,1)&MID(C11,2,1)&"-"&LEFT(E11,1)&MID(E11,2,1)&"-"&LEFT(G11,1)&MID(G11,2,1)&"-"&LEFT(H11,1)&MID(H11,2,1))) -> TO-SW-CO-NU-10 | E11: Cozy Cable-Knit Sweater | F11: A warm and stylish sweater for cooler days. | G11: Nude, Brown | H11: 10 | I11: 40 | J11: =ROUND((K11-I11)/I11*100,2) -> 75 | K11: 70
A12: 300 | B12: TOPS | C12: SWEATERS | D12: =CONCATENATE(UPPER(LEFT(B12,1)&MID(B12,2,1)&"-"&LEFT(C12,1)&MID(C12,2,1)&"-"&LEFT(E12,1)&MID(E12,2,1)&"-"&LEFT(G12,1)&MID(G12,2,1)&"-"&LEFT(H12,1)&MID(H12,2,1))) -> TO-SW-HO-BL-10 | E12: Hooded Sweatshirt | F12: A comfortable and casual sweatshirt perfect for lounging or layering. | G12: Black,Grey | H12: 10 | I12: 45 | J12: =ROUND((K12-I12)/I12*100,2) -> 51.11 | K12: 68
A13: 100 | B13: TOPS | C13: JACKETS | D13: =CONCATENATE(UPPER(LEFT(B13,1)&MID(B13,2,1)&"-"&LEFT(C13,1)&MID(C13,2,1)&"-"&LEFT(E13,1)&MID(E13,2,1)&"-"&LEFT(G13,1)&MID(G13,2,1)&"-"&LEFT(H13,1)&MID(H13,2,1))) -> TO-JA-DE-NU-10 | E13: Denim Jacket | F13: A timeless and versatile jacket that adds an edge to any outfit. | G13: Nude, Purple | H13: 10 | I13: 45 | J13: =ROUND((K13-I13)/I13*100,2) -> 88.89 | K13: 85
A14: 150 | B14: TOPS | C14: JACKETS | D14: =CONCATENATE(UPPER(LEFT(B14,1)&MID(B14,2,1)&"-"&LEFT(C14,1)&MID(C14,2,1)&"-"&LEFT(E14,1)&MID(E14,2,1)&"-"&LEFT(G14,1)&MID(G14,2,1)&"-"&LEFT(H14,1)&MID(H14,2,1))) -> TO-JA-LI-NU-10 | E14: Lightweight Puffer Jacket | F14: : A warm and packable jacket for all your adventures. | G14: Nude, Pink, Red | H14: 10 | I14: 65 | J14: =ROUND((K14-I14)/I14*100,2) -> 38.46 | K14: 90
B16: TOTAL NO OF PRODUCTS
B17: =SUM(A19:A35) -> 7134
A18: NO OF PRODUCTS | B18: CATEGORY | C18: SUB-CATEGORY | D18: REFERENCE | E18: PRODUCT NAME | F18: DESCRIPTION | G18: COLOUR | H18: SIZE | I18: COST PRICE (€) | J18: MARGIN (%) | K18: PRICE (€)
A19: 626 | B19: BOTTOMS | C19: JEANS | D19: =CONCATENATE(UPPER(LEFT(B19,1)&MID(B19,2,1)&"-"&LEFT(C19,1)&MID(C19,2,1)&"-"&LEFT(E19,1)&MID(E19,2,1)&"-"&LEFT(G19,1)&MID(G19,2,1)&"-"&LEFT(H19,1)&MID(H19,2,1))) -> BO-JE-CL-BL-10 | E19: Classic Straight Leg Jeans | F19: A timeless and versatile style that flatters all body types. | G19: Blue,Black,Grey | H19: 10 | I19: 35 | J19: =ROUND((K19-I19)/I19*100,2) -> 42.86 | K19: 50
A20: 207 | B20: BOTTOMS | C20: JEANS | D20: =CONCATENATE(UPPER(LEFT(B20,1)&MID(B20,2,1)&"-"&LEFT(C20,1)&MID(C20,2,1)&"-"&LEFT(E20,1)&MID(E20,2,1)&"-"&LEFT(G20,1)&MID(G20,2,1)&"-"&LEFT(H20,1)&MID(H20,2,1))) -> BO-JE-SK-BL-10 | E20: Skinny Fit Jeans | F20: A form-fitting silhouette that hugs your curves. | G20: Blue,Black,Grey | H20: 10 | I20: 30 | J20: =ROUND((K20-I20)/I20*100,2) -> 50 | K20: 45
A21: 644 | B21: BOTTOMS | C21: JEANS | D21: =CONCATENATE(UPPER(LEFT(B21,1)&MID(B21,2,1)&"-"&LEFT(C21,1)&MID(C21,2,1)&"-"&LEFT(E21,1)&MID(E21,2,1)&"-"&LEFT(G21,1)&MID(G21,2,1)&"-"&LEFT(H21,1)&MID(H21,2,1))) -> BO-JE-BO-BL-10 | E21: Bootcut Jeans | F21: A flattering style that flares slightly at the ankle. | G21: Blue,Black,Grey | H21: 10 | I21: 35 | J21: =ROUND((K21-I21)/I21*100,2) -> 37.14 | K21: 48
A22: 585 | B22: BOTTOMS | C22: JEANS | D22: =CONCATENATE(UPPER(LEFT(B22,1)&MID(B22,2,1)&"-"&LEFT(C22,1)&MID(C22,2,1)&"-"&LEFT(E22,1)&MID(E22,2,1)&"-"&LEFT(G22,1)&MID(G22,2,1)&"-"&LEFT(H22,1)&MID(H22,2,1))) -> BO-JE-HI-BL-10 | E22: High-Waisted Jeans | F22: A high-rise silhouette that elongates your legs and flatters your figure. | G22: Blue,Black,Grey | H22: 10 | I22: 38 | J22: =ROUND((K22-I22)/I22*100,2) -> 39.47 | K22: 53
A23: 597 | B23: BOTTOMS | C23: PANTS | D23: =CONCATENATE(UPPER(LEFT(B23,1)&MID(B23,2,1)&"-"&LEFT(C23,1)&MID(C23,2,1)&"-"&LEFT(E23,1)&MID(E23,2,1)&"-"&LEFT(G23,1)&MID(G23,2,1)&"-"&LEFT(H23,1)&MID(H23,2,1))) -> BO-PA-KH-BR-10 | E23: Khaki Chinos | F23: A versatile and comfortable option for work or casual wear. | G23: Brown,Black | H23: 10 | I23: 30 | J23: =ROUND((K23-I23)/I23*100,2) -> 33.33 | K23: 40
A24: 638 | B24: BOTTOMS | C24: PANTS | D24: =CONCATENATE(UPPER(LEFT(B24,1)&MID(B24,2,1)&"-"&LEFT(C24,1)&MID(C24,2,1)&"-"&LEFT(E24,1)&MID(E24,2,1)&"-"&LEFT(G24,1)&MID(G24,2,1)&"-"&LEFT(H24,1)&MID(H24,2,1))) -> BO-PA-SL-GR-10 | E24: Slim-Fit Dress Pants | F24: A polished and professional style for work or special occasions. | G24: green, yellow and lavender | H24: 10 | I24: 34 | J24: =ROUND((K24-I24)/I24*100,2) -> 61.76 | K24: 55
A25: 717 | B25: BOTTOMS | C25: PANTS | D25: =CONCATENATE(UPPER(LEFT(B25,1)&MID(B25,2,1)&"-"&LEFT(C25,1)&MID(C25,2,1)&"-"&LEFT(E25,1)&MID(E25,2,1)&"-"&LEFT(G25,1)&MID(G25,2,1)&"-"&LEFT(H25,1)&MID(H25,2,1))) -> BO-PA-UT-BL-10 | E25: Utility Cargo Pants | F25: A functional and stylish option with multiple pockets. | G25: Blue,Black,Grey | H25: 10 | I25: 25 | J25: =ROUND((K25-I25)/I25*100,2) -> 92 | K25: 48
A26: 755 | B26: BOTTOMS | C26: PANTS | D26: =CONCATENATE(UPPER(LEFT(B26,1)&MID(B26,2,1)&"-"&LEFT(C26,1)&MID(C26,2,1)&"-"&LEFT(E26,1)&MID(E26,2,1)&"-"&LEFT(G26,1)&MID(G26,2,1)&"-"&LEFT(H26,1)&MID(H26,2,1))) -> BO-PA-CO-GR-10 | E26: Cozy Joggers | F26: A comfortable and relaxed-fit style for lounging or exercising. | G26: Grey | H26: 10 | I26: 20 | J26: =ROUND((K26-I26)/I26*100,2) -> 75 | K26: 35
A27: 499 | B27: BOTTOMS | C27: PANTS | D27: =CONCATENATE(UPPER(LEFT(B27,1)&MID(B27,2,1)&"-"&LEFT(C27,1)&MID(C27,2,1)&"-"&LEFT(E27,1)&MID(E27,2,1)&"-"&LEFT(G27,1)&MID(G27,2,1)&"-"&LEFT(H27,1)&MID(H27,2,1))) -> BO-PA-TE-MU-10 | E27: Tech Fleece Track Pants | F27: Breathable and moisture-wicking pants for athletic activities or everyday wear. | G27: Multi-colors | H27: 10 | I27: 23 | J27: =ROUND((K27-I27)/I27*100,2) -> 86.96 | K27: 43
A28: 625 | B28: BOTTOMS | C28: SHORTS | D28: =CONCATENATE(UPPER(LEFT(B28,1)&MID(B28,2,1)&"-"&LEFT(C28,1)&MID(C28,2,1)&"-"&LEFT(E28,1)&MID(E28,2,1)&"-"&LEFT(G28,1)&MID(G28,2,1)&"-"&LEFT(H28,1)&MID(H28,2,1))) -> BO-SH-DI-LI-30 | E28: Distressed Denim Shorts | F28: A classic and casual style with a relaxed fit. | G28: light beige, medium beige, dark beige | H28: 30 | I28: 40 | J28: =ROUND((K28-I28)/I28*100,2) -> -25 | K28: 30
A29: 488 | B29: BOTTOMS | C29: SHORTS | D29: =CONCATENATE(UPPER(LEFT(B29,1)&MID(B29,2,1)&"-"&LEFT(C29,1)&MID(C29,2,1)&"-"&LEFT(E29,1)&MID(E29,2,1)&"-"&LEFT(G29,1)&MID(G29,2,1)&"-"&LEFT(H29,1)&MID(H29,2,1))) -> BO-SH-KH-LI-30 | E29: Khaki Chino Shorts | F29: A versatile option for warmer weather. | G29: light beige, Brown | H29: 30 | I29: 15 | J29: =ROUND((K29-I29)/I29*100,2) -> 66.67 | K29: 25
A30: 363 | B30: BOTTOMS | C30: SHORTS | D30: =CONCATENATE(UPPER(LEFT(B30,1)&MID(B30,2,1)&"-"&LEFT(C30,1)&MID(C30,2,1)&"-"&LEFT(E30,1)&MID(E30,2,1)&"-"&LEFT(G30,1)&MID(G30,2,1)&"-"&LEFT(H30,1)&MID(H30,2,1))) -> BO-SH-PE-MU-30 | E30: Performance Athletic Shorts | F30: Lightweight and breathable shorts for workouts or running. | G30: Multi-colors | H30: 30 | I30: 17 | J30: =ROUND((K30-I30)/I30*100,2) -> 94.12 | K30: 33
A31: 390 | B31: BOTTOMS | C31: SHORTS | D31: =CONCATENATE(UPPER(LEFT(B31,1)&MID(B31,2,1)&"-"&LEFT(C31,1)&MID(C31,2,1)&"-"&LEFT(E31,1)&MID(E31,2,1)&"-"&LEFT(G31,1)&MID(G31,2,1)&"-"&LEFT(H31,1)&MID(H31,2,1))) -> BO-SH-UT-GR-30 | E31: Utility Cargo Shorts | F31: Functional and stylish shorts with multiple pockets. | G31: Green,Brown,Black | H31: 30 | I31: 20 | J31: =ROUND((K31-I31)/I31*100,2) -> 100 | K31: 40
B38: TOTAL NO OF PRODUCTS
B39: =SUM(A41:A48) -> 3420
A40: NO OF PRODUCTS | B40: CATEGORY | C40: SUB-CATEGORY | D40: REFERENCE | E40: PRODUCT NAME | F40: DESCRIPTION | G40: COLOUR | H40: SIZE | I40: COST PRICE (€) | J40: MARGIN (%) | K40: PRICE (€)
A41: 488 | B41: SLEEPWEAR | C41: PAJAMAS | D41: =CONCATENATE(UPPER(LEFT(B41,1)&MID(B41,2,1)&"-"&LEFT(C41,1)&MID(C41,2,1)&"-"&LEFT(E41,1)&MID(E41,2,1)&"-"&LEFT(G41,1)&MID(G41,2,1)&"-"&LEFT(H41,1))) -> SL-PA-CO-MU-L | E41: Cozy Flannel Pajama Set | F41: A soft and warm set perfect for cooler nights. | G41: Multi-colors | H41: L,XL,XXL | I41: 25 | J41: =ROUND((K41-I41)/I41*100,2) -> 60 | K41: 40
A42: 267 | B42: SLEEPWEAR | C42: PAJAMAS | D42: =CONCATENATE(UPPER(LEFT(B42,1)&MID(B42,2,1)&"-"&LEFT(C42,1)&MID(C42,2,1)&"-"&LEFT(E42,1)&MID(E42,2,1)&"-"&LEFT(G42,1)&MID(G42,2,1)&"-"&LEFT(H42,1))) -> SL-PA-MO-MU-M | E42: Modal Jersey PJ Set | F42: A lightweight and breathable set for year-round comfort. | G42: Multi-colors | H42: M,L,XL,XXL | I42: 26 | J42: =ROUND((K42-I42)/I42*100,2) -> 73.08 | K42: 45
A43: 220 | B43: SLEEPWEAR | C43: PAJAMAS | D43: =CONCATENATE(UPPER(LEFT(B43,1)&MID(B43,2,1)&"-"&LEFT(C43,1)&MID(C43,2,1)&"-"&LEFT(E43,1)&MID(E43,2,1)&"-"&LEFT(G43,1)&MID(G43,2,1)&"-"&LEFT(H43,1))) -> SL-PA-ST-WH-L | E43: Striped Cotton Onesie | F43: A comfortable and playful option for lounging or sleeping. | G43: White,Grey | H43: L,XL,XXL | I43: 19 | J43: =ROUND((K43-I43)/I43*100,2) -> 57.89 | K43: 30
A44: 541 | B44: SLEEPWEAR | C44: PAJAMAS | D44: =CONCATENATE(UPPER(LEFT(B44,1)&MID(B44,2,1)&"-"&LEFT(C44,1)&MID(C44,2,1)&"-"&LEFT(E44,1)&MID(E44,2,1)&"-"&LEFT(G44,1)&MID(G44,2,1)&"-"&LEFT(H44,1))) -> SL-PA-FL-MU-L | E44: Floral Lace Nightgown | F44: A feminine and elegant nightgown for a luxurious feel. | G44: Multi-colors | H44: L,XL,XXL | I44: 27 | J44: =ROUND((K44-I44)/I44*100,2) -> 85.19 | K44: 50
A45: 586 | B45: SLEEPWEAR | C45: LOUNGEWEAR | D45: =CONCATENATE(UPPER(LEFT(B45,1)&MID(B45,2,1)&"-"&LEFT(C45,1)&MID(C45,2,1)&"-"&LEFT(E45,1)&MID(E45,2,1)&"-"&LEFT(G45,1)&MID(G45,2,1)&"-"&LEFT(H45,1))) -> SL-LO-FR-BL-S | E45: French Terry Loungewear Set | F45: A soft and stylish set for relaxing at home. | G45: Black,Dark Red | H45: S,L,XL,XXL | I45: 24 | J45: =ROUND((K45-I45)/I45*100,2) -> 79.17 | K45: 43
A46: 529 | B46: SLEEPWEAR | C46: LOUNGEWEAR | D46: =CONCATENATE(UPPER(LEFT(B46,1)&MID(B46,2,1)&"-"&LEFT(C46,1)&MID(C46,2,1)&"-"&LEFT(E46,1)&MID(E46,2,1)&"-"&LEFT(G46,1)&MID(G46,2,1)&"-"&LEFT(H46,1))) -> SL-LO-FL-BL-S | E46: Fleece Robe | F46: A warm and cozy robe perfect for mornings or evenings. | G46: Black | H46: S,L,XL,XXL | I46: 17 | J46: =ROUND((K46-I46)/I46*100,2) -> 105.88 | K46: 35
A47: 354 | B47: SLEEPWEAR | C47: LOUNGEWEAR | D47: =CONCATENATE(UPPER(LEFT(B47,1)&MID(B47,2,1)&"-"&LEFT(C47,1)&MID(C47,2,1)&"-"&LEFT(E47,1)&MID(E47,2,1)&"-"&LEFT(G47,1)&MID(G47,2,1)&"-"&LEFT(H47,1))) -> SL-LO-ME-BL-1 | E47: Memory Foam Slippers | F47: Plush and comfortable slippers for ultimate relaxation. | G47: Black,Grey | H47: 10 | I47: 14 | J47: =ROUND((K47-I47)/I47*100,2) -> 78.57 | K47: 25
A48: 435 | B48: SLEEPWEAR | C48: UNDERWEAR | D48: =CONCATENATE(UPPER(LEFT(B48,1)&MID(B48,2,1)&"-"&LEFT(C48,1)&MID(C48,2,1)&"-"&LEFT(E48,1)&MID(E48,2,1)&"-"&LEFT(G48,1)&MID(G48,2,1)&"-"&LEFT(H48,1))) -> SL-UN-SU-MU-L | E48: Supportive Sleep Bra | F48: Supportive Sleep Bra: Provides gentle support and comfort while sleeping. | G48: Multi-colors | H48: L,XL | I48: 15 | J48: =ROUND((K48-I48)/I48*100,2) -> 100 | K48: 30
A49: 175 | B49: SLEEPWEAR | C49: UNDERWEAR | D49: =CONCATENATE(UPPER(LEFT(B49,1)&MID(B49,2,1)&"-"&LEFT(C49,1)&MID(C49,2,1)&"-"&LEFT(E49,1)&MID(E49,2,1)&"-"&LEFT(G49,1)&MID(G49,2,1)&"-"&LEFT(H49,1))) -> SL-UN-SO-MU-L | E49: Soft Modal Sleep Shorts | F49: Breathable and lightweight shorts for a comfortable night's sleep. | G49: Multi-colors | H49: L,XL,XXL | I49: 12 | J49: =ROUND((K49-I49)/I49*100,2) -> 66.67 | K49: 20
...

Sheet WHS STK MGT & ALLOC.
A1: WAREHOUSE STOCK MANAGEMENT AND ALLOCATION
J4: WEEKLY STOCK ALLOCATION
A6: REFERENCE | B6: PRODUCT NAME | C6: CATEGORY | D6: SUB-CATEGORY | E6: DESCRIPTION | F6: COLOUR | G6: SIZE | H6: TOTAL STOCK | I6: REMANING STOCK | J6: 1ST WEEK % ALLOCATION | K6: 1ST WEEK | L6: 2ND WEEK % ALLOCATION | M6: 2ND WEEK | N6: 3RD WEEK % ALLOCATION | O6: 3RD WEEK | P6: 4TH WEEK % ALLOCATION | Q6: 4TH WEEK | R6: 5TH WEEK % ALLOCATION | S6: 5TH WEEK | T6: 6TH WEEK % ALLOCATION | U6: 6TH WEEK | V6: 7TH WEEK % ALLOCATION | W6: 7TH WEEK | X6: 8TH WEEK % ALLOCATION | Y6: 8TH WEEK
A7: TO-TE-CO-GR-58 | B7: =IFERROR(INDEX('REFERENCING & DATABASE'!$E$7:$E$131,MATCH($A7,'REFERENCING & DATABASE'!$D$7:$D$131,0)),"") -> Cozy Comfort Tee | C7: =IFERROR(INDEX('REFERENCING & DATABASE'!$B$7:$B$131,MATCH($A7,'REFERENCING & DATABASE'!$D$7:$D$131,0)),"") -> TOPS | D7: =IFERROR(INDEX('REFERENCING & DATABASE'!$C$7:$C$131,MATCH($A7,'REFERENCING & DATABASE'!$D$7:$D$131,0)),"") -> TEES | E7: =IFERROR(INDEX('REFERENCING & DATABASE'!$F$7:$F$131,MATCH($A7,'REFERENCING & DATABASE'!$D$7:$D$131,0)),"") -> A relaxed-fit tee made from super-soft cotton, perfect for everyday wear. | F7: =IFERROR(INDEX('REFERENCING & DATABASE'!$G$7:$G$131,MATCH($A7,'REFERENCING & DATABASE'!$D$7:$D$131,0)),"") -> Grey,Black,Blue | G7: =IFERROR(INDEX('REFERENCING & DATABASE'!$H$7:$H$131,MATCH($A7,'REFERENCING & DATABASE'!$D$7:$D$131,0)),"") -> 58 | H7: =IFERROR(INDEX('REFERENCING & DATABASE'!$A$7:$A$131,MATCH($A7,'REFERENCING & DATABASE'!$D$7:$D$131,0)),"") -> 450 | I7: =H7-SUM($K7,$M7,$O7,$Q7) -> 400 | J7: =ROUND((($K7/$H7)*100),3) -> 11.111 | K7: =SUMIFS('IN STORE SALES RECORD'!$E$6:$E$97,'IN STORE SALES RECORD'!$A$6:$A$97, "WEEK 1",'IN STORE SALES RECORD'!$D$6:$D$97,'WHS STK MGT & ALLOC.'!$A7)+10 -> 50 | L7: =ROUND(($M7/($H7-$K7))*100,3) -> 0 | M7: =SUMIFS('IN STORE SALES RECORD'!$E$6:$E$97,'IN STORE SALES RECORD'!$A$6:$A$97, "WEEK 6",'IN STORE SALES RECORD'!$D$6:$D$97,'WHS STK MGT & ALLOC.'!$A7) -> 0 | N7: =ROUND(($O7/($H7-($M7+$K7))*100),3) -> 0 | O7: =SUMIFS('IN STORE SALES RECORD'!$E$6:$E$97,'IN STORE SALES RECORD'!$A$6:$A$97, "WEEK 6",'IN STORE SALES RECORD'!$D$6:$D$97,'WHS STK MGT & ALLOC.'!$A7) -> 0 | P7: =ROUND(($Q7/($H7-($M7+$K7+$O7))*100),3) -> 0 | Q7: =SUMIFS('IN STORE SALES RECORD'!$E$6:$E$97,'IN STORE SALES RECORD'!$A$6:$A$97, "WEEK 6",'IN STORE SALES RECORD'!$D$6:$D$97,'WHS STK MGT & ALLOC.'!$A7) -> 0 | R7: =ROUND(($S7/($H7-($M7+$K7+$O7+$Q7))*100),3) -> 0 | S7: =SUMIFS('IN STORE SALES RECORD'!$E$6:$E$97,'IN STORE SALES RECORD'!$A$6:$A$97, "WEEK 6",'IN STORE SALES RECORD'!$D$6:$D$97,'WHS STK MGT & ALLOC.'!$A7) -> 0 | T7: =ROUND(($U7/($H7-($M7+$K7+$O7+$Q7+$S7))*100),3) -> 0 | U7: =SUMIFS('IN STORE SALES RECORD'!$E$6:$E$97,'IN STORE SALES RECORD'!$A$6:$A$97, "WEEK 6",'IN STORE SALES RECORD'!$D$6:$D$97,'WHS STK MGT & ALLOC.'!$A7) -> 0 | V7: =ROUND(($W7/($H7-($M7+$K7+$O7+$Q7+$S7+$U7))*100),3) -> 0 | W7: =SUMIFS('IN STORE SALES RECORD'!$E$6:$E$97,'IN STORE SALES RECORD'!$A$6:$A$97, "WEEK 6",'IN STORE SALES RECORD'!$D$6:$D$97,'WHS STK MGT & ALLOC.'!$A7) -> 0 | X7: =ROUND(($Y7/($H7-($M7+$K7+$O7+$Q7+$S7+$U7+$W7))*100),3) -> 0 | Y7: =SUMIFS('IN STORE SALES RECORD'!$E$6:$E$97,'IN STORE SALES RECORD'!$A$6:$A$97, "WEEK 6",'IN STORE SALES RECORD'!$D$6:$D$97,'WHS STK MGT & ALLOC.'!$A7) -> 0
A8: TO-TE-GR-BL-58 | B8: =IFERROR(INDEX('REFERENCING & DATABASE'!$E$7:$E$131,MATCH($A8,'REFERENCING & DATABASE'!$D$7:$D$131,0)),"") -> Graphic Statement Tee | C8: =IFERROR(INDEX('REFERENCING & DATABASE'!$B$7:$B$131,MATCH($A8,'REFERENCING & DATABASE'!$D$7:$D$131,0)),"") -> TOPS | D8: =IFERROR(INDEX('REFERENCING & DATABASE'!$C$7:$C$131,MATCH($A8,'REFERENCING & DATABASE'!$D$7:$D$131,0)),"") -> TEES | E8: =IFERROR(INDEX('REFERENCING & DATABASE'!$F$7:$F$131,MATCH($A8,'REFERENCING & DATABASE'!$D$7:$D$131,0)),"") -> A bold graphic tee that expresses your unique style. | F8: =IFERROR(INDEX('REFERENCING & DATABASE'!$G$7:$G$131,MATCH($A8,'REFERENCING & DATABASE'!$D$7:$D$131,0)),"") -> Blue,Black,White | G8: =IFERROR(INDEX('REFERENCING & DATABASE'!$H$7:$H$131,MATCH($A8,'REFERENCING & DATABASE'!$D$7:$D$131,0)),"") -> 58 | H8: =IFERROR(INDEX('REFERENCING & DATABASE'!$A$7:$A$131,MATCH($A8,'REFERENCING & DATABASE'!$D$7:$D$131,0)),"") -> 300 | I8: =H8-SUM($K8,$M8,$O8,$Q8) -> 290 | J8: =ROUND((($K8/$H8)*100),3) -> 3.333 | K8: =SUMIFS('IN STORE SALES RECORD'!$E$6:$E$97,'IN STORE SALES RECORD'!$A$6:$A$97, "WEEK 1",'IN STORE SALES RECORD'!$D$6:$D$97,'WHS STK MGT & ALLOC.'!$A8)+10 -> 10 | L8: =ROUND(($M8/($H8-$K8))*100,3) -> 0 | M8: =SUMIFS('IN STORE SALES RECORD'!$E$6:$E$97,'IN STORE SALES RECORD'!$A$6:$A$97, "WEEK 6",'IN STORE SALES RECORD'!$D$6:$D$97,'WHS STK MGT & ALLOC.'!$A8) -> 0 | N8: =ROUND(($O8/($H8-($M8+$K8))*100),3) -> 0 | O8: =SUMIFS('IN STORE SALES RECORD'!$E$6:$E$97,'IN STORE SALES RECORD'!$A$6:$A$97, "WEEK 6",'IN STORE SALES RECORD'!$D$6:$D$97,'WHS STK MGT & ALLOC.'!$A8) -> 0 | P8: =ROUND(($Q8/($H8-($M8+$K8+$O8))*100),3) -> 0 | Q8: =SUMIFS('IN STORE SALES RECORD'!$E$6:$E$97,'IN STORE SALES RECORD'!$A$6:$A$97, "WEEK 6",'IN STORE SALES RECORD'!$D$6:$D$97,'WHS STK MGT & ALLOC.'!$A8) -> 0 | R8: =ROUND(($S8/($H8-($M8+$K8+$O8+$Q8))*100),3) -> 0 | S8: =SUMIFS('IN STORE SALES RECORD'!$E$6:$E$97,'IN STORE SALES RECORD'!$A$6:$A$97, "WEEK 6",'IN STORE SALES RECORD'!$D$6:$D$97,'WHS STK MGT & ALLOC.'!$A8) -> 0 | T8: =ROUND(($U8/($H8-($M8+$K8+$O8+$Q8+$S8))*100),3) -> 0 | U8: =SUMIFS('IN STORE SALES RECORD'!$E$6:$E$97,'IN STORE SALES RECORD'!$A$6:$A$97, "WEEK 6",'IN STORE SALES RECORD'!$D$6:$D$97,'WHS STK MGT & ALLOC.'!$A8) -> 0 | V8: =ROUND(($W8/($H8-($M8+$K8+$O8+$Q8+$S8+$U8))*100),3) -> 0 | W8: =SUMIFS('IN STORE SALES RECORD'!$E$6:$E$97,'IN STORE SALES RECORD'!$A$6:$A$97, "WEEK 6",'IN STORE SALES RECORD'!$D$6:$D$97,'WHS STK MGT & ALLOC.'!$A8) -> 0 | X8: =ROUND(($Y8/($H8-($M8+$K8+$O8+$Q8+$S8+$U8+$W8))*100),3) -> 0 | Y8: =SUMIFS('IN STORE SALES RECORD'!$E$6:$E$97,'IN STORE SALES RECORD'!$A$6:$A$97, "WEEK 6",'IN STORE SALES RECORD'!$D$6:$D$97,'WHS STK MGT & ALLOC.'!$A8) -> 0
A9: TO-SH-CL-PI-10 | B9: =IFERROR(INDEX('REFERENCING & DATABASE'!$E$7:$E$131,MATCH($A9,'REFERENCING & DATABASE'!$D$7:$D$131,0)),"") -> Classic Button-Down Shirt | C9: =IFERROR(INDEX('REFERENCING & DATABASE'!$B$7:$B$131,MATCH($A9,'REFERENCING & DATABASE'!$D$7:$D$131,0)),"") -> TOPS | D9: =IFERROR(INDEX('REFERENCING & DATABASE'!$C$7:$C$131,MATCH($A9,'REFERENCING & DATABASE'!$D$7:$D$131,0)),"") -> SHIRTS | E9: =IFERROR(INDEX('REFERENCING & DATABASE'!$F$7:$F$131,MATCH($A9,'REFERENCING & DATABASE'!$D$7:$D$131,0)),"") -> A timeless and versatile shirt for work or casual occasions. | F9: =IFERROR(INDEX('REFERENCING & DATABASE'!$G$7:$G$131,MATCH($A9,'REFERENCING & DATABASE'!$D$7:$D$131,0)),"") -> Pink, Brown,Yellow | G9: =IFERROR(INDEX('REFERENCING & DATABASE'!$H$7:$H$131,MATCH($A9,'REFERENCING & DATABASE'!$D$7:$D$131,0)),"") -> 10 | H9: =IFERROR(INDEX('REFERENCING & DATABASE'!$A$7:$A$131,MATCH($A9,'REFERENCING & DATABASE'!$D$7:$D$131,0)),"") -> 300 | I9: =H9-SUM($K9,$M9,$O9,$Q9,$S9,$U9,$W9,$Y9) -> 60 | J9: =ROUND((($K9/$H9)*100),3) -> 80 | K9: =SUMIFS('IN STORE SALES RECORD'!$E$6:$E$97,'IN STORE SALES RECORD'!$A$6:$A$97, "WEEK 1",'IN STORE SALES RECORD'!$D$6:$D$97,'WHS STK MGT & ALLOC.'!$A9)+10 -> 240 | L9: =ROUND(($M9/($H9-$K9))*100,3) -> 0 | M9: =SUMIFS('IN STORE SALES RECORD'!$E$6:$E$97,'IN STORE SALES RECORD'!$A$6:$A$97, "WEEK 6",'IN STORE SALES RECORD'!$D$6:$D$97,'WHS STK MGT & ALLOC.'!$A9) -> 0 | N9: =ROUND(($O9/($H9-($M9+$K9))*100),3) -> 0 | O9: =SUMIFS('IN STORE SALES RECORD'!$E$6:$E$97,'IN STORE SALES RECORD'!$A$6:$A$97, "WEEK 6",'IN STORE SALES RECORD'!$D$6:$D$97,'WHS STK MGT & ALLOC.'!$A9) -> 0 | P9: =ROUND(($Q9/($H9-($M9+$K9+$O9))*100),3) -> 0 | Q9: =SUMIFS('IN STORE SALES RECORD'!$E$6:$E$97,'IN STORE SALES RECORD'!$A$6:$A$97, "WEEK 6",'IN STORE SALES RECORD'!$D$6:$D$97,'WHS STK MGT & ALLOC.'!$A9) -> 0 | R9: =ROUND(($S9/($H9-($M9+$K9+$O9+$Q9))*100),3) -> 0 | S9: =SUMIFS('IN STORE SALES RECORD'!$E$6:$E$97,'IN STORE SALES RECORD'!$A$6:$A$97, "WEEK 6",'IN STORE SALES RECORD'!$D$6:$D$97,'WHS STK MGT & ALLOC.'!$A9) -> 0 | T9: =ROUND(($U9/($H9-($M9+$K9+$O9+$Q9+$S9))*100),3) -> 0 | U9: =SUMIFS('IN STORE SALES RECORD'!$E$6:$E$97,'IN STORE SALES RECORD'!$A$6:$A$97, "WEEK 6",'IN STORE SALES RECORD'!$D$6:$D$97,'WHS STK MGT & ALLOC.'!$A9) -> 0 | V9: =ROUND(($W9/($H9-($M9+$K9+$O9+$Q9+$S9+$U9))*100),3) -> 0 | W9: =SUMIFS('IN STORE SALES RECORD'!$E$6:$E$97,'IN STORE SALES RECORD'!$A$6:$A$97, "WEEK 6",'IN STORE SALES RECORD'!$D$6:$D$97,'WHS STK MGT & ALLOC.'!$A9) -> 0 | X9: =ROUND(($Y9/($H9-($M9+$K9+$O9+$Q9+$S9+$U9+$W9))*100),3) -> 0 | Y9: =SUMIFS('IN STORE SALES RECORD'!$E$6:$E$97,'IN STORE SALES RECORD'!$A$6:$A$97, "WEEK 6",'IN STORE SALES RECORD'!$D$6:$D$97,'WHS STK MGT & ALLOC.'!$A9) -> 0
A10: TO-SH-LI-PI-10 | B10: =IFERROR(INDEX('REFERENCING & DATABASE'!$E$7:$E$131,MATCH($A10,'REFERENCING & DATABASE'!$D$7:$D$131,0)),"") -> Linen Blend Shirt | C10: =IFERROR(INDEX('REFERENCING & DATABASE'!$B$7:$B$131,MATCH($A10,'REFERENCING & DATABASE'!$D$7:$D$131,0)),"") -> TOPS | D10: =IFERROR(INDEX('REFERENCING & DATABASE'!$C$7:$C$131,MATCH($A10,'REFERENCING & DATABASE'!$D$7:$D$131,0)),"") -> SHIRTS | E10: =IFERROR(INDEX('REFERENCING & DATABASE'!$F$7:$F$131,MATCH($A10,'REFERENCING & DATABASE'!$D$7:$D$131,0)),"") -> A lightweight and breathable shirt for warmer weather. | F10: =IFERROR(INDEX('REFERENCING & DATABASE'!$G$7:$G$131,MATCH($A10,'REFERENCING & DATABASE'!$D$7:$D$131,0)),"") -> Pink, Clear | G10: =IFERROR(INDEX('REFERENCING & DATABASE'!$H$7:$H$131,MATCH($A10,'REFERENCING & DATABASE'!$D$7:$D$131,0)),"") -> 10 | H10: =IFERROR(INDEX('REFERENCING & DATABASE'!$A$7:$A$131,MATCH($A10,'REFERENCING & DATABASE'!$D$7:$D$131,0)),"") -> 400 | I10: =H10-SUM($K10,$M10,$O10,$Q10) -> 390 | J10: =ROUND((($K10/$H10)*100),3) -> 2.5 | K10: =SUMIFS('IN STORE SALES RECORD'!$E$6:$E$97,'IN STORE SALES RECORD'!$A$6:$A$97, "WEEK 1",'IN STORE SALES RECORD'!$D$6:$D$97,'WHS STK MGT & ALLOC.'!$A10)+10 -> 10 | L10: =ROUND(($M10/($H10-$K10))*100,3) -> 0 | M10: =SUMIFS('IN STORE SALES RECORD'!$E$6:$E$97,'IN STORE SALES RECORD'!$A$6:$A$97, "WEEK 6",'IN STORE SALES RECORD'!$D$6:$D$97,'WHS STK MGT & ALLOC.'!$A10) -> 0 | N10: =ROUND(($O10/($H10-($M10+$K10))*100),3) -> 0 | O10: =SUMIFS('IN STORE SALES RECORD'!$E$6:$E$97,'IN STORE SALES RECORD'!$A$6:$A$97, "WEEK 6",'IN STORE SALES RECORD'!$D$6:$D$97,'WHS STK MGT & ALLOC.'!$A10) -> 0 | P10: =ROUND(($Q10/($H10-($M10+$K10+$O10))*100),3) -> 0 | Q10: =SUMIFS('IN STORE SALES RECORD'!$E$6:$E$97,'IN STORE SALES RECORD'!$A$6:$A$97, "WEEK 6",'IN STORE SALES RECORD'!$D$6:$D$97,'WHS STK MGT & ALLOC.'!$A10) -> 0 | R10: =ROUND(($S10/($H10-($M10+$K10+$O10+$Q10))*100),3) -> 0 | S10: =SUMIFS('IN STORE SALES RECORD'!$E$6:$E$97,'IN STORE SALES RECORD'!$A$6:$A$97, "WEEK 6",'IN STORE SALES RECORD'!$D$6:$D$97,'WHS STK MGT & ALLOC.'!$A10) -> 0 | T10: =ROUND(($U10/($H10-($M10+$K10+$O10+$Q10+$S10))*100),3) -> 0 | U10: =SUMIFS('IN STORE SALES RECORD'!$E$6:$E$97,'IN STORE SALES RECORD'!$A$6:$A$97, "WEEK 6",'IN STORE SALES RECORD'!$D$6:$D$97,'WHS STK MGT & ALLOC.'!$A10) -> 0 | V10: =ROUND(($W10/($H10-($M10+$K10+$O10+$Q10+$S10+$U10))*100),3) -> 0 | W10: =SUMIFS('IN STORE SALES RECORD'!$E$6:$E$97,'IN STORE SALES RECORD'!$A$6:$A$97, "WEEK 6",'IN STORE SALES RECORD'!$D$6:$D$97,'WHS STK MGT & ALLOC.'!$A10) -> 0 | X10: =ROUND(($Y10/($H10-($M10+$K10+$O10+$Q10+$S10+$U10+$W10))*100),3) -> 0 | Y10: =SUMIFS('IN STORE SALES RECORD'!$E$6:$E$97,'IN STORE SALES RECORD'!$A$6:$A$97, "WEEK 6",'IN STORE SALES RECORD'!$D$6:$D$97,'WHS STK MGT & ALLOC.'!$A10) -> 0
A11: TO-SW-CO-NU-10 | B11: =IFERROR(INDEX('REFERENCING & DATABASE'!$E$7:$E$131,MATCH($A11,'REFERENCING & DATABASE'!$D$7:$D$131,0)),"") -> Cozy Cable-Knit Sweater | C11: =IFERROR(INDEX('REFERENCING & DATABASE'!$B$7:$B$131,MATCH($A11,'REFERENCING & DATABASE'!$D$7:$D$131,0)),"") -> TOPS | D11: =IFERROR(INDEX('REFERENCING & DATABASE'!$C$7:$C$131,MATCH($A11,'REFERENCING & DATABASE'!$D$7:$D$131,0)),"") -> SWEATERS | E11: =IFERROR(INDEX('REFERENCING & DATABASE'!$F$7:$F$131,MATCH($A11,'REFERENCING & DATABASE'!$D$7:$D$131,0)),"") -> A warm and stylish sweater for cooler days. | F11: =IFERROR(INDEX('REFERENCING & DATABASE'!$G$7:$G$131,MATCH($A11,'REFERENCING & DATABASE'!$D$7:$D$131,0)),"") -> Nude, Brown | G11: =IFERROR(INDEX('REFERENCING & DATABASE'!$H$7:$H$131,MATCH($A11,'REFERENCING & DATABASE'!$D$7:$D$131,0)),"") -> 10 | H11: =IFERROR(INDEX('REFERENCING & DATABASE'!$A$7:$A$131,MATCH($A11,'REFERENCING & DATABASE'!$D$7:$D$131,0)),"") -> 200 | I11: =H11-SUM($K11,$M11,$O11,$Q11) -> 190 | J11: =ROUND((($K11/$H11)*100),3) -> 5 | K11: =SUMIFS('IN STORE SALES RECORD'!$E$6:$E$97,'IN STORE SALES RECORD'!$A$6:$A$97, "WEEK 1",'IN STORE SALES RECORD'!$D$6:$D$97,'WHS STK MGT & ALLOC.'!$A11)+10 -> 10 | L11: =ROUND(($M11/($H11-$K11))*100,3) -> 0 | M11: =SUMIFS('IN STORE SALES RECORD'!$E$6:$E$97,'IN STORE SALES RECORD'!$A$6:$A$97, "WEEK 6",'IN STORE SALES RECORD'!$D$6:$D$97,'WHS STK MGT & ALLOC.'!$A11) -> 0 | N11: =ROUND(($O11/($H11-($M11+$K11))*100),3) -> 0 | O11: =SUMIFS('IN STORE SALES RECORD'!$E$6:$E$97,'IN STORE SALES RECORD'!$A$6:$A$97, "WEEK 6",'IN STORE SALES RECORD'!$D$6:$D$97,'WHS STK MGT & ALLOC.'!$A11) -> 0 | P11: =ROUND(($Q11/($H11-($M11+$K11+$O11))*100),3) -> 0 | Q11: =SUMIFS('IN STORE SALES RECORD'!$E$6:$E$97,'IN STORE SALES RECORD'!$A$6:$A$97, "WEEK 6",'IN STORE SALES RECORD'!$D$6:$D$97,'WHS STK MGT & ALLOC.'!$A11) -> 0 | R11: =ROUND(($S11/($H11-($M11+$K11+$O11+$Q11))*100),3) -> 0 | S11: =SUMIFS('IN STORE SALES RECORD'!$E$6:$E$97,'IN STORE SALES RECORD'!$A$6:$A$97, "WEEK 6",'IN STORE SALES RECORD'!$D$6:$D$97,'WHS STK MGT & ALLOC.'!$A11) -> 0 | T11: =ROUND(($U11/($H11-($M11+$K11+$O11+$Q11+$S11))*100),3) -> 0 | U11: =SUMIFS('IN STORE SALES RECORD'!$E$6:$E$97,'IN STORE SALES RECORD'!$A$6:$A$97, "WEEK 6",'IN STORE SALES RECORD'!$D$6:$D$97,'WHS STK MGT & ALLOC.'!$A11) -> 0 | V11: =ROUND(($W11/($H11-($M11+$K11+$O11+$Q11+$S11+$U11))*100),3) -> 0 | W11: =SUMIFS('IN STORE SALES RECORD'!$E$6:$E$97,'IN STORE SALES RECORD'!$A$6:$A$97, "WEEK 6",'IN STORE SALES RECORD'!$D$6:$D$97,'WHS STK MGT & ALLOC.'!$A11) -> 0 | X11: =ROUND(($Y11/($H11-($M11+$K11+$O11+$Q11+$S11+$U11+$W11))*100),3) -> 0 | Y11: =SUMIFS('IN STORE SALES RECORD'!$E$6:$E$97,'IN STORE SALES RECORD'!$A$6:$A$97, "WEEK 6",'IN STORE SALES RECORD'!$D$6:$D$97,'WHS STK MGT & ALLOC.'!$A11) -> 0
A12: TO-SW-HO-BL-10 | B12: =IFERROR(INDEX('REFERENCING & DATABASE'!$E$7:$E$131,MATCH($A12,'REFERENCING & DATABASE'!$D$7:$D$131,0)),"") -> Hooded Sweatshirt | C12: =IFERROR(INDEX('REFERENCING & DATABASE'!$B$7:$B$131,MATCH($A12,'REFERENCING & DATABASE'!$D$7:$D$131,0)),"") -> TOPS | D12: =IFERROR(INDEX('REFERENCING & DATABASE'!$C$7:$C$131,MATCH($A12,'REFERENCING & DATABASE'!$D$7:$D$131,0)),"") -> SWEATERS | E12: =IFERROR(INDEX('REFERENCING & DATABASE'!$F$7:$F$131,MATCH($A12,'REFERENCING & DATABASE'!$D$7:$D$131,0)),"") -> A comfortable and casual sweatshirt perfect for lounging or layering. | F12: =IFERROR(INDEX('REFERENCING & DATABASE'!$G$7:$G$131,MATCH($A12,'REFERENCING & DATABASE'!$D$7:$D$131,0)),"") -> Black,Grey | G12: =IFERROR(INDEX('REFERENCING & DATABASE'!$H$7:$H$131,MATCH($A12,'REFERENCING & DATABASE'!$D$7:$D$131,0)),"") -> 10 | H12: =IFERROR(INDEX('REFERENCING & DATABASE'!$A$7:$A$131,MATCH($A12,'REFERENCING & DATABASE'!$D$7:$D$131,0)),"") -> 300 | I12: =H12-SUM($K12,$M12,$O12,$Q12) -> 290 | J12: =ROUND((($K12/$H12)*100),3) -> 3.333 | K12: =SUMIFS('IN STORE SALES RECORD'!$E$6:$E$97,'IN STORE SALES RECORD'!$A$6:$A$97, "WEEK 1",'IN STORE SALES RECORD'!$D$6:$D$97,'WHS STK MGT & ALLOC.'!$A12)+10 -> 10 | L12: =ROUND(($M12/($H12-$K12))*100,3) -> 0 | M12: =SUMIFS('IN STORE SALES RECORD'!$E$6:$E$97,'IN STORE SALES RECORD'!$A$6:$A$97, "WEEK 6",'IN STORE SALES RECORD'!$D$6:$D$97,'WHS STK MGT & ALLOC.'!$A12) -> 0 | N12: =ROUND(($O12/($H12-($M12+$K12))*100),3) -> 0 | O12: =SUMIFS('IN STORE SALES RECORD'!$E$6:$E$97,'IN STORE SALES RECORD'!$A$6:$A$97, "WEEK 6",'IN STORE SALES RECORD'!$D$6:$D$97,'WHS STK MGT & ALLOC.'!$A12) -> 0 | P12: =ROUND(($Q12/($H12-($M12+$K12+$O12))*100),3) -> 0 | Q12: =SUMIFS('IN STORE SALES RECORD'!$E$6:$E$97,'IN STORE SALES RECORD'!$A$6:$A$97, "WEEK 6",'IN STORE SALES RECORD'!$D$6:$D$97,'WHS STK MGT & ALLOC.'!$A12) -> 0 | R12: =ROUND(($S12/($H12-($M12+$K12+$O12+$Q12))*100),3) -> 0 | S12: =SUMIFS('IN STORE SALES RECORD'!$E$6:$E$97,'IN STORE SALES RECORD'!$A$6:$A$97, "WEEK 6",'IN STORE SALES RECORD'!$D$6:$D$97,'WHS STK MGT & ALLOC.'!$A12) -> 0 | T12: =ROUND(($U12/($H12-($M12+$K12+$O12+$Q12+$S12))*100),3) -> 0 | U12: =SUMIFS('IN STORE SALES RECORD'!$E$6:$E$97,'IN STORE SALES RECORD'!$A$6:$A$97, "WEEK 6",'IN STORE SALES RECORD'!$D$6:$D$97,'WHS STK MGT & ALLOC.'!$A12) -> 0 | V12: =ROUND(($W12/($H12-($M12+$K12+$O12+$Q12+$S12+$U12))*100),3) -> 0 | W12: =SUMIFS('IN STORE SALES RECORD'!$E$6:$E$97,'IN STORE SALES RECORD'!$A$6:$A$97, "WEEK 6",'IN STORE SALES RECORD'!$D$6:$D$97,'WHS STK MGT & ALLOC.'!$A12) -> 0 | X12: =ROUND(($Y12/($H12-($M12+$K12+$O12+$Q12+$S12+$U12+$W12))*100),3) -> 0 | Y12: =SUMIFS('IN STORE SALES RECORD'!$E$6:$E$97,'IN STORE SALES RECORD'!$A$6:$A$97, "WEEK 6",'IN STORE SALES RECORD'!$D$6:$D$97,'WHS STK MGT & ALLOC.'!$A12) -> 0
A13: TO-JA-DE-NU-10 | B13: =IFERROR(INDEX('REFERENCING & DATABASE'!$E$7:$E$131,MATCH($A13,'REFERENCING & DATABASE'!$D$7:$D$131,0)),"") -> Denim Jacket | C13: =IFERROR(INDEX('REFERENCING & DATABASE'!$B$7:$B$131,MATCH($A13,'REFERENCING & DATABASE'!$D$7:$D$131,0)),"") -> TOPS | D13: =IFERROR(INDEX('REFERENCING & DATABASE'!$C$7:$C$131,MATCH($A13,'REFERENCING & DATABASE'!$D$7:$D$131,0)),"") -> JACKETS | E13: =IFERROR(INDEX('REFERENCING & DATABASE'!$F$7:$F$131,MATCH($A13,'REFERENCING & DATABASE'!$D$7:$D$131,0)),"") -> A timeless and versatile jacket that adds an edge to any outfit. | F13: =IFERROR(INDEX('REFERENCING & DATABASE'!$G$7:$G$131,MATCH($A13,'REFERENCING & DATABASE'!$D$7:$D$131,0)),"") -> Nude, Purple | G13: =IFERROR(INDEX('REFERENCING & DATABASE'!$H$7:$H$131,MATCH($A13,'REFERENCING & DATABASE'!$D$7:$D$131,0)),"") -> 10 | H13: =IFERROR(INDEX('REFERENCING & DATABASE'!$A$7:$A$131,MATCH($A13,'REFERENCING & DATABASE'!$D$7:$D$131,0)),"") -> 100 | I13: =H13-SUM($K13,$M13,$O13,$Q13) -> 90 | J13: =ROUND((($K13/$H13)*100),3) -> 10 | K13: =SUMIFS('IN STORE SALES RECORD'!$E$6:$E$97,'IN STORE SALES RECORD'!$A$6:$A$97, "WEEK 1",'IN STORE SALES RECORD'!$D$6:$D$97,'WHS STK MGT & ALLOC.'!$A13)+10 -> 10 | L13: =ROUND(($M13/($H13-$K13))*100,3) -> 0 | M13: =SUMIFS('IN STORE SALES RECORD'!$E$6:$E$97,'IN STORE SALES RECORD'!$A$6:$A$97, "WEEK 6",'IN STORE SALES RECORD'!$D$6:$D$97,'WHS STK MGT & ALLOC.'!$A13) -> 0 | N13: =ROUND(($O13/($H13-($M13+$K13))*100),3) -> 0 | O13: =SUMIFS('IN STORE SALES RECORD'!$E$6:$E$97,'IN STORE SALES RECORD'!$A$6:$A$97, "WEEK 6",'IN STORE SALES RECORD'!$D$6:$D$97,'WHS STK MGT & ALLOC.'!$A13) -> 0 | P13: =ROUND(($Q13/($H13-($M13+$K13+$O13))*100),3) -> 0 | Q13: =SUMIFS('IN STORE SALES RECORD'!$E$6:$E$97,'IN STORE SALES RECORD'!$A$6:$A$97, "WEEK 6",'IN STORE SALES RECORD'!$D$6:$D$97,'WHS STK MGT & ALLOC.'!$A13) -> 0 | R13: =ROUND(($S13/($H13-($M13+$K13+$O13+$Q13))*100),3) -> 0 | S13: =SUMIFS('IN STORE SALES RECORD'!$E$6:$E$97,'IN STORE SALES RECORD'!$A$6:$A$97, "WEEK 6",'IN STORE SALES RECORD'!$D$6:$D$97,'WHS STK MGT & ALLOC.'!$A13) -> 0 | T13: =ROUND(($U13/($H13-($M13+$K13+$O13+$Q13+$S13))*100),3) -> 0 | U13: =SUMIFS('IN STORE SALES RECORD'!$E$6:$E$97,'IN STORE SALES RECORD'!$A$6:$A$97, "WEEK 6",'IN STORE SALES RECORD'!$D$6:$D$97,'WHS STK MGT & ALLOC.'!$A13) -> 0 | V13: =ROUND(($W13/($H13-($M13+$K13+$O13+$Q13+$S13+$U13))*100),3) -> 0 | W13: =SUMIFS('IN STORE SALES RECORD'!$E$6:$E$97,'IN STORE SALES RECORD'!$A$6:$A$97, "WEEK 6",'IN STORE SALES RECORD'!$D$6:$D$97,'WHS STK MGT & ALLOC.'!$A13) -> 0 | X13: =ROUND(($Y13/($H13-($M13+$K13+$O13+$Q13+$S13+$U13+$W13))*100),3) -> 0 | Y13: =SUMIFS('IN STORE SALES RECORD'!$E$6:$E$97,'IN STORE SALES RECORD'!$A$6:$A$97, "WEEK 6",'IN STORE SALES RECORD'!$D$6:$D$97,'WHS STK MGT & ALLOC.'!$A13) -> 0
A14: TO-JA-LI-NU-10 | B14: =IFERROR(INDEX('REFERENCING & DATABASE'!$E$7:$E$131,MATCH($A14,'REFERENCING & DATABASE'!$D$7:$D$131,0)),"") -> Lightweight Puffer Jacket | C14: =IFERROR(INDEX('REFERENCING & DATABASE'!$B$7:$B$131,MATCH($A14,'REFERENCING & DATABASE'!$D$7:$D$131,0)),"") -> TOPS | D14: =IFERROR(INDEX('REFERENCING & DATABASE'!$C$7:$C$131,MATCH($A14,'REFERENCING & DATABASE'!$D$7:$D$131,0)),"") -> JACKETS | E14: =IFERROR(INDEX('REFERENCING & DATABASE'!$F$7:$F$131,MATCH($A14,'REFERENCING & DATABASE'!$D$7:$D$131,0)),"") -> : A warm and packable jacket for all your adventures. | F14: =IFERROR(INDEX('REFERENCING & DATABASE'!$G$7:$G$131,MATCH($A14,'REFERENCING & DATABASE'!$D$7:$D$131,0)),"") -> Nude, Pink, Red | G14: =IFERROR(INDEX('REFERENCING & DATABASE'!$H$7:$H$131,MATCH($A14,'REFERENCING & DATABASE'!$D$7:$D$131,0)),"") -> 10 | H14: =IFERROR(INDEX('REFERENCING & DATABASE'!$A$7:$A$131,MATCH($A14,'REFERENCING & DATABASE'!$D$7:$D$131,0)),"") -> 150 | I14: =H14-SUM($K14,$M14,$O14,$Q14) -> 140 | J14: =ROUND((($K14/$H14)*100),3) -> 6.667 | K14: =SUMIFS('IN STORE SALES RECORD'!$E$6:$E$97,'IN STORE SALES RECORD'!$A$6:$A$97, "WEEK 1",'IN STORE SALES RECORD'!$D$6:$D$97,'WHS STK MGT & ALLOC.'!$A14)+10 -> 10 | L14: =ROUND(($M14/($H14-$K14))*100,3) -> 0 | M14: =SUMIFS('IN STORE SALES RECORD'!$E$6:$E$97,'IN STORE SALES RECORD'!$A$6:$A$97, "WEEK 6",'IN STORE SALES RECORD'!$D$6:$D$97,'WHS STK MGT & ALLOC.'!$A14) -> 0 | N14: =ROUND(($O14/($H14-($M14+$K14))*100),3) -> 0 | O14: =SUMIFS('IN STORE SALES RECORD'!$E$6:$E$97,'IN STORE SALES RECORD'!$A$6:$A$97, "WEEK 6",'IN STORE SALES RECORD'!$D$6:$D$97,'WHS STK MGT & ALLOC.'!$A14) -> 0 | P14: =ROUND(($Q14/($H14-($M14+$K14+$O14))*100),3) -> 0 | Q14: =SUMIFS('IN STORE SALES RECORD'!$E$6:$E$97,'IN STORE SALES RECORD'!$A$6:$A$97, "WEEK 6",'IN STORE SALES RECORD'!$D$6:$D$97,'WHS STK MGT & ALLOC.'!$A14) -> 0 | R14: =ROUND(($S14/($H14-($M14+$K14+$O14+$Q14))*100),3) -> 0 | S14: =SUMIFS('IN STORE SALES RECORD'!$E$6:$E$97,'IN STORE SALES RECORD'!$A$6:$A$97, "WEEK 6",'IN STORE SALES RECORD'!$D$6:$D$97,'WHS STK MGT & ALLOC.'!$A14) -> 0 | T14: =ROUND(($U14/($H14-($M14+$K14+$O14+$Q14+$S14))*100),3) -> 0 | U14: =SUMIFS('IN STORE SALES RECORD'!$E$6:$E$97,'IN STORE SALES RECORD'!$A$6:$A$97, "WEEK 6",'IN STORE SALES RECORD'!$D$6:$D$97,'WHS STK MGT & ALLOC.'!$A14) -> 0 | V14: =ROUND(($W14/($H14-($M14+$K14+$O14+$Q14+$S14+$U14))*100),3) -> 0 | W14: =SUMIFS('IN STORE SALES RECORD'!$E$6:$E$97,'IN STORE SALES RECORD'!$A$6:$A$97, "WEEK 6",'IN STORE SALES RECORD'!$D$6:$D$97,'WHS STK MGT & ALLOC.'!$A14) -> 0 | X14: =ROUND(($Y14/($H14-($M14+$K14+$O14+$Q14+$S14+$U14+$W14))*100),3) -> 0 | Y14: =SUMIFS('IN STORE SALES RECORD'!$E$6:$E$97,'IN STORE SALES RECORD'!$A$6:$A$97, "WEEK 6",'IN STORE SALES RECORD'!$D$6:$D$97,'WHS STK MGT & ALLOC.'!$A14) -> 0
A18: =A$6 -> REFERENCE | B18: =B$6 -> PRODUCT NAME | C18: =C$6 -> CATEGORY | D18: =D$6 -> SUB-CATEGORY | E18: =E$6 -> DESCRIPTION | F18: =F$6 -> COLOUR | G18: =G$6 -> SIZE | H18: =H$6 -> TOTAL STOCK | ... Q18: =Q$6 -> 4TH WEEK | R18: 5TH WEEK % ALLOCATION | S18: 5TH WEEK | T18: 6TH WEEK % ALLOCATION | U18: 6TH WEEK | V18: 7TH WEEK % ALLOCATION | W18: 7TH WEEK | X18: 8TH WEEK % ALLOCATION | Y18: 8TH WEEK
A19: BO-JE-CL-BL-10 | B19: =IFERROR(INDEX('REFERENCING & DATABASE'!$E$7:$E$131,MATCH($A19,'REFERENCING & DATABASE'!$D$7:$D$131,0)),"") -> Classic Straight Leg Jeans | C19: =IFERROR(INDEX('REFERENCING & DATABASE'!$B$7:$B$131,MATCH($A19,'REFERENCING & DATABASE'!$D$7:$D$131,0)),"") -> BOTTOMS | D19: =IFERROR(INDEX('REFERENCING & DATABASE'!$C$7:$C$131,MATCH($A19,'REFERENCING & DATABASE'!$D$7:$D$131,0)),"") -> JEANS | E19: =IFERROR(INDEX('REFERENCING & DATABASE'!$F$7:$F$131,MATCH($A19,'REFERENCING & DATABASE'!$D$7:$D$131,0)),"") -> A timeless and versatile style that flatters all body types. | F19: =IFERROR(INDEX('REFERENCING & DATABASE'!$G$7:$G$131,MATCH($A19,'REFERENCING & DATABASE'!$D$7:$D$131,0)),"") -> Blue,Black,Grey | G19: =IFERROR(INDEX('REFERENCING & DATABASE'!$H$7:$H$131,MATCH($A19,'REFERENCING & DATABASE'!$D$7:$D$131,0)),"") -> 10 | H19: =IFERROR(INDEX('REFERENCING & DATABASE'!$A$7:$A$131,MATCH($A19,'REFERENCING & DATABASE'!$D$7:$D$131,0)),"") -> 626 | I19: =H19-SUM($K19,$M19,$O19,$Q19) -> 616 | J19: =ROUND((($K19/$H19)*100),3) -> 1.597 | K19: =SUMIFS('IN STORE SALES RECORD'!$E$6:$E$97,'IN STORE SALES RECORD'!$A$6:$A$97, "WEEK 1",'IN STORE SALES RECORD'!$D$6:$D$97,'WHS STK MGT & ALLOC.'!$A19)+10 -> 10 | L19: =ROUND(($M19/($H19-$K19))*100,3) -> 0 | M19: =SUMIFS('IN STORE SALES RECORD'!$E$6:$E$97,'IN STORE SALES RECORD'!$A$6:$A$97, "WEEK 6",'IN STORE SALES RECORD'!$D$6:$D$97,'WHS STK MGT & ALLOC.'!$A19) -> 0 | N19: =ROUND(($O19/($H19-($M19+$K19))*100),3) -> 0 | O19: =SUMIFS('IN STORE SALES RECORD'!$E$6:$E$97,'IN STORE SALES RECORD'!$A$6:$A$97, "WEEK 6",'IN STORE SALES RECORD'!$D$6:$D$97,'WHS STK MGT & ALLOC.'!$A19) -> 0 | P19: =ROUND(($Q19/($H19-($M19+$K19+$O19))*100),3) -> 0 | Q19: =SUMIFS('IN STORE SALES RECORD'!$E$6:$E$97,'IN STORE SALES RECORD'!$A$6:$A$97, "WEEK 6",'IN STORE SALES RECORD'!$D$6:$D$97,'WHS STK MGT & ALLOC.'!$A19) -> 0 | R19: =ROUND(($S19/($H19-($M19+$K19+$O19+$Q19))*100),3) -> 0 | S19: =SUMIFS('IN STORE SALES RECORD'!$E$6:$E$97,'IN STORE SALES RECORD'!$A$6:$A$97, "WEEK 6",'IN STORE SALES RECORD'!$D$6:$D$97,'WHS STK MGT & ALLOC.'!$A19) -> 0 | T19: =ROUND(($U19/($H19-($M19+$K19+$O19+$Q19+$S19))*100),3) -> 0 | U19: =SUMIFS('IN STORE SALES RECORD'!$E$6:$E$97,'IN STORE SALES RECORD'!$A$6:$A$97, "WEEK 6",'IN STORE SALES RECORD'!$D$6:$D$97,'WHS STK MGT & ALLOC.'!$A19) -> 0 | V19: =ROUND(($W19/($H19-($M19+$K19+$O19+$Q19+$S19+$U19))*100),3) -> 0 | W19: =SUMIFS('IN STORE SALES RECORD'!$E$6:$E$97,'IN STORE SALES RECORD'!$A$6:$A$97, "WEEK 6",'IN STORE SALES RECORD'!$D$6:$D$97,'WHS STK MGT & ALLOC.'!$A19) -> 0 | X19: =ROUND(($Y19/($H19-($M19+$K19+$O19+$Q19+$S19+$U19+$W19))*100),3) -> 0 | Y19: =SUMIFS('IN STORE SALES RECORD'!$E$6:$E$97,'IN STORE SALES RECORD'!$A$6:$A$97, "WEEK 6",'IN STORE SALES RECORD'!$D$6:$D$97,'WHS STK MGT & ALLOC.'!$A19) -> 0
A20: BO-JE-SK-BL-10 | B20: =IFERROR(INDEX('REFERENCING & DATABASE'!$E$7:$E$131,MATCH($A20,'REFERENCING & DATABASE'!$D$7:$D$131,0)),"") -> Skinny Fit Jeans | C20: =IFERROR(INDEX('REFERENCING & DATABASE'!$B$7:$B$131,MATCH($A20,'REFERENCING & DATABASE'!$D$7:$D$131,0)),"") -> BOTTOMS | D20: =IFERROR(INDEX('REFERENCING & DATABASE'!$C$7:$C$131,MATCH($A20,'REFERENCING & DATABASE'!$D$7:$D$131,0)),"") -> JEANS | E20: =IFERROR(INDEX('REFERENCING & DATABASE'!$F$7:$F$131,MATCH($A20,'REFERENCING & DATABASE'!$D$7:$D$131,0)),"") -> A form-fitting silhouette that hugs your curves. | F20: =IFERROR(INDEX('REFERENCING & DATABASE'!$G$7:$G$131,MATCH($A20,'REFERENCING & DATABASE'!$D$7:$D$131,0)),"") -> Blue,Black,Grey | G20: =IFERROR(INDEX('REFERENCING & DATABASE'!$H$7:$H$131,MATCH($A20,'REFERENCING & DATABASE'!$D$7:$D$131,0)),"") -> 10 | H20: =IFERROR(INDEX('REFERENCING & DATABASE'!$A$7:$A$131,MATCH($A20,'REFERENCING & DATABASE'!$D$7:$D$131,0)),"") -> 207 | I20: =H20-SUM($K20,$M20,$O20,$Q20) -> 197 | J20: =ROUND((($K20/$H20)*100),3) -> 4.831 | K20: =SUMIFS('IN STORE SALES RECORD'!$E$6:$E$97,'IN STORE SALES RECORD'!$A$6:$A$97, "WEEK 1",'IN STORE SALES RECORD'!$D$6:$D$97,'WHS STK MGT & ALLOC.'!$A20)+10 -> 10 | L20: =ROUND(($M20/($H20-$K20))*100,3) -> 0 | M20: =SUMIFS('IN STORE SALES RECORD'!$E$6:$E$97,'IN STORE SALES RECORD'!$A$6:$A$97, "WEEK 6",'IN STORE SALES RECORD'!$D$6:$D$97,'WHS STK MGT & ALLOC.'!$A20) -> 0 | N20: =ROUND(($O20/($H20-($M20+$K20))*100),3) -> 0 | O20: =SUMIFS('IN STORE SALES RECORD'!$E$6:$E$97,'IN STORE SALES RECORD'!$A$6:$A$97, "WEEK 6",'IN STORE SALES RECORD'!$D$6:$D$97,'WHS STK MGT & ALLOC.'!$A20) -> 0 | P20: =ROUND(($Q20/($H20-($M20+$K20+$O20))*100),3) -> 0 | Q20: =SUMIFS('IN STORE SALES RECORD'!$E$6:$E$97,'IN STORE SALES RECORD'!$A$6:$A$97, "WEEK 6",'IN STORE SALES RECORD'!$D$6:$D$97,'WHS STK MGT & ALLOC.'!$A20) -> 0 | R20: =ROUND(($S20/($H20-($M20+$K20+$O20+$Q20))*100),3) -> 0 | S20: =SUMIFS('IN STORE SALES RECORD'!$E$6:$E$97,'IN STORE SALES RECORD'!$A$6:$A$97, "WEEK 6",'IN STORE SALES RECORD'!$D$6:$D$97,'WHS STK MGT & ALLOC.'!$A20) -> 0 | T20: =ROUND(($U20/($H20-($M20+$K20+$O20+$Q20+$S20))*100),3) -> 0 | U20: =SUMIFS('IN STORE SALES RECORD'!$E$6:$E$97,'IN STORE SALES RECORD'!$A$6:$A$97, "WEEK 6",'IN STORE SALES RECORD'!$D$6:$D$97,'WHS STK MGT & ALLOC.'!$A20) -> 0 | V20: =ROUND(($W20/($H20-($M20+$K20+$O20+$Q20+$S20+$U20))*100),3) -> 0 | W20: =SUMIFS('IN STORE SALES RECORD'!$E$6:$E$97,'IN STORE SALES RECORD'!$A$6:$A$97, "WEEK 6",'IN STORE SALES RECORD'!$D$6:$D$97,'WHS STK MGT & ALLOC.'!$A20) -> 0 | X20: =ROUND(($Y20/($H20-($M20+$K20+$O20+$Q20+$S20+$U20+$W20))*100),3) -> 0 | Y20: =SUMIFS('IN STORE SALES RECORD'!$E$6:$E$97,'IN STORE SALES RECORD'!$A$6:$A$97, "WEEK 6",'IN STORE SALES RECORD'!$D$6:$D$97,'WHS STK MGT & ALLOC.'!$A20) -> 0
A21: BO-JE-BO-BL-10 | B21: =IFERROR(INDEX('REFERENCING & DATABASE'!$E$7:$E$131,MATCH($A21,'REFERENCING & DATABASE'!$D$7:$D$131,0)),"") -> Bootcut Jeans | C21: =IFERROR(INDEX('REFERENCING & DATABASE'!$B$7:$B$131,MATCH($A21,'REFERENCING & DATABASE'!$D$7:$D$131,0)),"") -> BOTTOMS | D21: =IFERROR(INDEX('REFERENCING & DATABASE'!$C$7:$C$131,MATCH($A21,'REFERENCING & DATABASE'!$D$7:$D$131,0)),"") -> JEANS | E21: =IFERROR(INDEX('REFERENCING & DATABASE'!$F$7:$F$131,MATCH($A21,'REFERENCING & DATABASE'!$D$7:$D$131,0)),"") -> A flattering style that flares slightly at the ankle. | F21: =IFERROR(INDEX('REFERENCING & DATABASE'!$G$7:$G$131,MATCH($A21,'REFERENCING & DATABASE'!$D$7:$D$131,0)),"") -> Blue,Black,Grey | G21: =IFERROR(INDEX('REFERENCING & DATABASE'!$H$7:$H$131,MATCH($A21,'REFERENCING & DATABASE'!$D$7:$D$131,0)),"") -> 10 | H21: =IFERROR(INDEX('REFERENCING & DATABASE'!$A$7:$A$131,MATCH($A21,'REFERENCING & DATABASE'!$D$7:$D$131,0)),"") -> 644 | I21: =H21-SUM($K21,$M21,$O21,$Q21) -> 634 | J21: =ROUND((($K21/$H21)*100),3) -> 1.553 | K21: =SUMIFS('IN STORE SALES RECORD'!$E$6:$E$97,'IN STORE SALES RECORD'!$A$6:$A$97, "WEEK 1",'IN STORE SALES RECORD'!$D$6:$D$97,'WHS STK MGT & ALLOC.'!$A21)+10 -> 10 | L21: =ROUND(($M21/($H21-$K21))*100,3) -> 0 | M21: =SUMIFS('IN STORE SALES RECORD'!$E$6:$E$97,'IN STORE SALES RECORD'!$A$6:$A$97, "WEEK 6",'IN STORE SALES RECORD'!$D$6:$D$97,'WHS STK MGT & ALLOC.'!$A21) -> 0 | N21: =ROUND(($O21/($H21-($M21+$K21))*100),3) -> 0 | O21: =SUMIFS('IN STORE SALES RECORD'!$E$6:$E$97,'IN STORE SALES RECORD'!$A$6:$A$97, "WEEK 6",'IN STORE SALES RECORD'!$D$6:$D$97,'WHS STK MGT & ALLOC.'!$A21) -> 0 | P21: =ROUND(($Q21/($H21-($M21+$K21+$O21))*100),3) -> 0 | Q21: =SUMIFS('IN STORE SALES RECORD'!$E$6:$E$97,'IN STORE SALES RECORD'!$A$6:$A$97, "WEEK 6",'IN STORE SALES RECORD'!$D$6:$D$97,'WHS STK MGT & ALLOC.'!$A21) -> 0 | R21: =ROUND(($S21/($H21-($M21+$K21+$O21+$Q21))*100),3) -> 0 | S21: =SUMIFS('IN STORE SALES RECORD'!$E$6:$E$97,'IN STORE SALES RECORD'!$A$6:$A$97, "WEEK 6",'IN STORE SALES RECORD'!$D$6:$D$97,'WHS STK MGT & ALLOC.'!$A21) -> 0 | T21: =ROUND(($U21/($H21-($M21+$K21+$O21+$Q21+$S21))*100),3) -> 0 | U21: =SUMIFS('IN STORE SALES RECORD'!$E$6:$E$97,'IN STORE SALES RECORD'!$A$6:$A$97, "WEEK 6",'IN STORE SALES RECORD'!$D$6:$D$97,'WHS STK MGT & ALLOC.'!$A21) -> 0 | V21: =ROUND(($W21/($H21-($M21+$K21+$O21+$Q21+$S21+$U21))*100),3) -> 0 | W21: =SUMIFS('IN STORE SALES RECORD'!$E$6:$E$97,'IN STORE SALES RECORD'!$A$6:$A$97, "WEEK 6",'IN STORE SALES RECORD'!$D$6:$D$97,'WHS STK MGT & ALLOC.'!$A21) -> 0 | X21: =ROUND(($Y21/($H21-($M21+$K21+$O21+$Q21+$S21+$U21+$W21))*100),3) -> 0 | Y21: =SUMIFS('IN STORE SALES RECORD'!$E$6:$E$97,'IN STORE SALES RECORD'!$A$6:$A$97, "WEEK 6",'IN STORE SALES RECORD'!$D$6:$D$97,'WHS STK MGT & ALLOC.'!$A21) -> 0
A22: BO-JE-HI-BL-10 | B22: =IFERROR(INDEX('REFERENCING & DATABASE'!$E$7:$E$131,MATCH($A22,'REFERENCING & DATABASE'!$D$7:$D$131,0)),"") -> High-Waisted Jeans | C22: =IFERROR(INDEX('REFERENCING & DATABASE'!$B$7:$B$131,MATCH($A22,'REFERENCING & DATABASE'!$D$7:$D$131,0)),"") -> BOTTOMS | D22: =IFERROR(INDEX('REFERENCING & DATABASE'!$C$7:$C$131,MATCH($A22,'REFERENCING & DATABASE'!$D$7:$D$131,0)),"") -> JEANS | E22: =IFERROR(INDEX('REFERENCING & DATABASE'!$F$7:$F$131,MATCH($A22,'REFERENCING & DATABASE'!$D$7:$D$131,0)),"") -> A high-rise silhouette that elongates your legs and flatters your figure. | F22: =IFERROR(INDEX('REFERENCING & DATABASE'!$G$7:$G$131,MATCH($A22,'REFERENCING & DATABASE'!$D$7:$D$131,0)),"") -> Blue,Black,Grey | G22: =IFERROR(INDEX('REFERENCING & DATABASE'!$H$7:$H$131,MATCH($A22,'REFERENCING & DATABASE'!$D$7:$D$131,0)),"") -> 10 | H22: =IFERROR(INDEX('REFERENCING & DATABASE'!$A$7:$A$131,MATCH($A22,'REFERENCING & DATABASE'!$D$7:$D$131,0)),"") -> 585 | I22: =H22-SUM($K22,$M22,$O22,$Q22) -> 485 | J22: =ROUND((($K22/$H22)*100),3) -> 17.094 | K22: =SUMIFS('IN STORE SALES RECORD'!$E$6:$E$97,'IN STORE SALES RECORD'!$A$6:$A$97, "WEEK 1",'IN STORE SALES RECORD'!$D$6:$D$97,'WHS STK MGT & ALLOC.'!$A22)+10 -> 100 | L22: =ROUND(($M22/($H22-$K22))*100,3) -> 0 | M22: =SUMIFS('IN STORE SALES RECORD'!$E$6:$E$97,'IN STORE SALES RECORD'!$A$6:$A$97, "WEEK 6",'IN STORE SALES RECORD'!$D$6:$D$97,'WHS STK MGT & ALLOC.'!$A22) -> 0 | N22: =ROUND(($O22/($H22-($M22+$K22))*100),3) -> 0 | O22: =SUMIFS('IN STORE SALES RECORD'!$E$6:$E$97,'IN STORE SALES RECORD'!$A$6:$A$97, "WEEK 6",'IN STORE SALES RECORD'!$D$6:$D$97,'WHS STK MGT & ALLOC.'!$A22) -> 0 | P22: =ROUND(($Q22/($H22-($M22+$K22+$O22))*100),3) -> 0 | Q22: =SUMIFS('IN STORE SALES RECORD'!$E$6:$E$97,'IN STORE SALES RECORD'!$A$6:$A$97, "WEEK 6",'IN STORE SALES RECORD'!$D$6:$D$97,'WHS STK MGT & ALLOC.'!$A22) -> 0 | R22: =ROUND(($S22/($H22-($M22+$K22+$O22+$Q22))*100),3) -> 0 | S22: =SUMIFS('IN STORE SALES RECORD'!$E$6:$E$97,'IN STORE SALES RECORD'!$A$6:$A$97, "WEEK 6",'IN STORE SALES RECORD'!$D$6:$D$97,'WHS STK MGT & ALLOC.'!$A22) -> 0 | T22: =ROUND(($U22/($H22-($M22+$K22+$O22+$Q22+$S22))*100),3) -> 0 | U22: =SUMIFS('IN STORE SALES RECORD'!$E$6:$E$97,'IN STORE SALES RECORD'!$A$6:$A$97, "WEEK 6",'IN STORE SALES RECORD'!$D$6:$D$97,'WHS STK MGT & ALLOC.'!$A22) -> 0 | V22: =ROUND(($W22/($H22-($M22+$K22+$O22+$Q22+$S22+$U22))*100),3) -> 0 | W22: =SUMIFS('IN STORE SALES RECORD'!$E$6:$E$97,'IN STORE SALES RECORD'!$A$6:$A$97, "WEEK 6",'IN STORE SALES RECORD'!$D$6:$D$97,'WHS STK MGT & ALLOC.'!$A22) -> 0 | X22: =ROUND(($Y22/($H22-($M22+$K22+$O22+$Q22+$S22+$U22+$W22))*100),3) -> 0 | Y22: =SUMIFS('IN STORE SALES RECORD'!$E$6:$E$97,'IN STORE SALES RECORD'!$A$6:$A$97, "WEEK 6",'IN STORE SALES RECORD'!$D$6:$D$97,'WHS STK MGT & ALLOC.'!$A22) -> 0
A23: BO-PA-KH-BR-10 | B23: =IFERROR(INDEX('REFERENCING & DATABASE'!$E$7:$E$131,MATCH($A23,'REFERENCING & DATABASE'!$D$7:$D$131,0)),"") -> Khaki Chinos | C23: =IFERROR(INDEX('REFERENCING & DATABASE'!$B$7:$B$131,MATCH($A23,'REFERENCING & DATABASE'!$D$7:$D$131,0)),"") -> BOTTOMS | D23: =IFERROR(INDEX('REFERENCING & DATABASE'!$C$7:$C$131,MATCH($A23,'REFERENCING & DATABASE'!$D$7:$D$131,0)),"") -> PANTS | E23: =IFERROR(INDEX('REFERENCING & DATABASE'!$F$7:$F$131,MATCH($A23,'REFERENCING & DATABASE'!$D$7:$D$131,0)),"") -> A versatile and comfortable option for work or casual wear. | F23: =IFERROR(INDEX('REFERENCING & DATABASE'!$G$7:$G$131,MATCH($A23,'REFERENCING & DATABASE'!$D$7:$D$131,0)),"") -> Brown,Black | G23: =IFERROR(INDEX('REFERENCING & DATABASE'!$H$7:$H$131,MATCH($A23,'REFERENCING & DATABASE'!$D$7:$D$131,0)),"") -> 10 | H23: =IFERROR(INDEX('REFERENCING & DATABASE'!$A$7:$A$131,MATCH($A23,'REFERENCING & DATABASE'!$D$7:$D$131,0)),"") -> 597 | I23: =H23-SUM($K23,$M23,$O23,$Q23) -> 587 | J23: =ROUND((($K23/$H23)*100),3) -> 1.675 | K23: =SUMIFS('IN STORE SALES RECORD'!$E$6:$E$97,'IN STORE SALES RECORD'!$A$6:$A$97, "WEEK 1",'IN STORE SALES RECORD'!$D$6:$D$97,'WHS STK MGT & ALLOC.'!$A23)+10 -> 10 | L23: =ROUND(($M23/($H23-$K23))*100,3) -> 0 | M23: =SUMIFS('IN STORE SALES RECORD'!$E$6:$E$97,'IN STORE SALES RECORD'!$A$6:$A$97, "WEEK 6",'IN STORE SALES RECORD'!$D$6:$D$97,'WHS STK MGT & ALLOC.'!$A23) -> 0 | N23: =ROUND(($O23/($H23-($M23+$K23))*100),3) -> 0 | O23: =SUMIFS('IN STORE SALES RECORD'!$E$6:$E$97,'IN STORE SALES RECORD'!$A$6:$A$97, "WEEK 6",'IN STORE SALES RECORD'!$D$6:$D$97,'WHS STK MGT & ALLOC.'!$A23) -> 0 | P23: =ROUND(($Q23/($H23-($M23+$K23+$O23))*100),3) -> 0 | Q23: =SUMIFS('IN STORE SALES RECORD'!$E$6:$E$97,'IN STORE SALES RECORD'!$A$6:$A$97, "WEEK 6",'IN STORE SALES RECORD'!$D$6:$D$97,'WHS STK MGT & ALLOC.'!$A23) -> 0 | R23: =ROUND(($S23/($H23-($M23+$K23+$O23+$Q23))*100),3) -> 0 | S23: =SUMIFS('IN STORE SALES RECORD'!$E$6:$E$97,'IN STORE SALES RECORD'!$A$6:$A$97, "WEEK 6",'IN STORE SALES RECORD'!$D$6:$D$97,'WHS STK MGT & ALLOC.'!$A23) -> 0 | T23: =ROUND(($U23/($H23-($M23+$K23+$O23+$Q23+$S23))*100),3) -> 0 | U23: =SUMIFS('IN STORE SALES RECORD'!$E$6:$E$97,'IN STORE SALES RECORD'!$A$6:$A$97, "WEEK 6",'IN STORE SALES RECORD'!$D$6:$D$97,'WHS STK MGT & ALLOC.'!$A23) -> 0 | V23: =ROUND(($W23/($H23-($M23+$K23+$O23+$Q23+$S23+$U23))*100),3) -> 0 | W23: =SUMIFS('IN STORE SALES RECORD'!$E$6:$E$97,'IN STORE SALES RECORD'!$A$6:$A$97, "WEEK 6",'IN STORE SALES RECORD'!$D$6:$D$97,'WHS STK MGT & ALLOC.'!$A23) -> 0 | X23: =ROUND(($Y23/($H23-($M23+$K23+$O23+$Q23+$S23+$U23+$W23))*100),3) -> 0 | Y23: =SUMIFS('IN STORE SALES RECORD'!$E$6:$E$97,'IN STORE SALES RECORD'!$A$6:$A$97, "WEEK 6",'IN STORE SALES RECORD'!$D$6:$D$97,'WHS STK MGT & ALLOC.'!$A23) -> 0
A24: BO-PA-SL-GR-10 | B24: =IFERROR(INDEX('REFERENCING & DATABASE'!$E$7:$E$131,MATCH($A24,'REFERENCING & DATABASE'!$D$7:$D$131,0)),"") -> Slim-Fit Dress Pants | C24: =IFERROR(INDEX('REFERENCING & DATABASE'!$B$7:$B$131,MATCH($A24,'REFERENCING & DATABASE'!$D$7:$D$131,0)),"") -> BOTTOMS | D24: =IFERROR(INDEX('REFERENCING & DATABASE'!$C$7:$C$131,MATCH($A24,'REFERENCING & DATABASE'!$D$7:$D$131,0)),"") -> PANTS | E24: =IFERROR(INDEX('REFERENCING & DATABASE'!$F$7:$F$131,MATCH($A24,'REFERENCING & DATABASE'!$D$7:$D$131,0)),"") -> A polished and professional style for work or special occasions. | F24: =IFERROR(INDEX('REFERENCING & DATABASE'!$G$7:$G$131,MATCH($A24,'REFERENCING & DATABASE'!$D$7:$D$131,0)),"") -> green, yellow and lavender | G24: =IFERROR(INDEX('REFERENCING & DATABASE'!$H$7:$H$131,MATCH($A24,'REFERENCING & DATABASE'!$D$7:$D$131,0)),"") -> 10 | H24: =IFERROR(INDEX('REFERENCING & DATABASE'!$A$7:$A$131,MATCH($A24,'REFERENCING & DATABASE'!$D$7:$D$131,0)),"") -> 638 | I24: =H24-SUM($K24,$M24,$O24,$Q24) -> 628 | J24: =ROUND((($K24/$H24)*100),3) -> 1.567 | K24: =SUMIFS('IN STORE SALES RECORD'!$E$6:$E$97,'IN STORE SALES RECORD'!$A$6:$A$97, "WEEK 1",'IN STORE SALES RECORD'!$D$6:$D$97,'WHS STK MGT & ALLOC.'!$A24)+10 -> 10 | L24: =ROUND(($M24/($H24-$K24))*100,3) -> 0 | M24: =SUMIFS('IN STORE SALES RECORD'!$E$6:$E$97,'IN STORE SALES RECORD'!$A$6:$A$97, "WEEK 6",'IN STORE SALES RECORD'!$D$6:$D$97,'WHS STK MGT & ALLOC.'!$A24) -> 0 | N24: =ROUND(($O24/($H24-($M24+$K24))*100),3) -> 0 | O24: =SUMIFS('IN STORE SALES RECORD'!$E$6:$E$97,'IN STORE SALES RECORD'!$A$6:$A$97, "WEEK 6",'IN STORE SALES RECORD'!$D$6:$D$97,'WHS STK MGT & ALLOC.'!$A24) -> 0 | P24: =ROUND(($Q24/($H24-($M24+$K24+$O24))*100),3) -> 0 | Q24: =SUMIFS('IN STORE SALES RECORD'!$E$6:$E$97,'IN STORE SALES RECORD'!$A$6:$A$97, "WEEK 6",'IN STORE SALES RECORD'!$D$6:$D$97,'WHS STK MGT & ALLOC.'!$A24) -> 0 | R24: =ROUND(($S24/($H24-($M24+$K24+$O24+$Q24))*100),3) -> 0 | S24: =SUMIFS('IN STORE SALES RECORD'!$E$6:$E$97,'IN STORE SALES RECORD'!$A$6:$A$97, "WEEK 6",'IN STORE SALES RECORD'!$D$6:$D$97,'WHS STK MGT & ALLOC.'!$A24) -> 0 | T24: =ROUND(($U24/($H24-($M24+$K24+$O24+$Q24+$S24))*100),3) -> 0 | U24: =SUMIFS('IN STORE SALES RECORD'!$E$6:$E$97,'IN STORE SALES RECORD'!$A$6:$A$97, "WEEK 6",'IN STORE SALES RECORD'!$D$6:$D$97,'WHS STK MGT & ALLOC.'!$A24) -> 0 | V24: =ROUND(($W24/($H24-($M24+$K24+$O24+$Q24+$S24+$U24))*100),3) -> 0 | W24: =SUMIFS('IN STORE SALES RECORD'!$E$6:$E$97,'IN STORE SALES RECORD'!$A$6:$A$97, "WEEK 6",'IN STORE SALES RECORD'!$D$6:$D$97,'WHS STK MGT & ALLOC.'!$A24) -> 0 | X24: =ROUND(($Y24/($H24-($M24+$K24+$O24+$Q24+$S24+$U24+$W24))*100),3) -> 0 | Y24: =SUMIFS('IN STORE SALES RECORD'!$E$6:$E$97,'IN STORE SALES RECORD'!$A$6:$A$97, "WEEK 6",'IN STORE SALES RECORD'!$D$6:$D$97,'WHS STK MGT & ALLOC.'!$A24) -> 0
A25: BO-PA-UT-BL-10 | B25: =IFERROR(INDEX('REFERENCING & DATABASE'!$E$7:$E$131,MATCH($A25,'REFERENCING & DATABASE'!$D$7:$D$131,0)),"") -> Utility Cargo Pants | C25: =IFERROR(INDEX('REFERENCING & DATABASE'!$B$7:$B$131,MATCH($A25,'REFERENCING & DATABASE'!$D$7:$D$131,0)),"") -> BOTTOMS | D25: =IFERROR(INDEX('REFERENCING & DATABASE'!$C$7:$C$131,MATCH($A25,'REFERENCING & DATABASE'!$D$7:$D$131,0)),"") -> PANTS | E25: =IFERROR(INDEX('REFERENCING & DATABASE'!$F$7:$F$131,MATCH($A25,'REFERENCING & DATABASE'!$D$7:$D$131,0)),"") -> A functional and stylish option with multiple pockets. | F25: =IFERROR(INDEX('REFERENCING & DATABASE'!$G$7:$G$131,MATCH($A25,'REFERENCING & DATABASE'!$D$7:$D$131,0)),"") -> Blue,Black,Grey | G25: =IFERROR(INDEX('REFERENCING & DATABASE'!$H$7:$H$131,MATCH($A25,'REFERENCING & DATABASE'!$D$7:$D$131,0)),"") -> 10 | H25: =IFERROR(INDEX('REFERENCING & DATABASE'!$A$7:$A$131,MATCH($A25,'REFERENCING & DATABASE'!$D$7:$D$131,0)),"") -> 717 | I25: =H25-SUM($K25,$M25,$O25,$Q25) -> 707 | J25: =ROUND((($K25/$H25)*100),3) -> 1.395 | K25: =SUMIFS('IN STORE SALES RECORD'!$E$6:$E$97,'IN STORE SALES RECORD'!$A$6:$A$97, "WEEK 1",'IN STORE SALES RECORD'!$D$6:$D$97,'WHS STK MGT & ALLOC.'!$A25)+10 -> 10 | L25: =ROUND(($M25/($H25-$K25))*100,3) -> 0 | M25: =SUMIFS('IN STORE SALES RECORD'!$E$6:$E$97,'IN STORE SALES RECORD'!$A$6:$A$97, "WEEK 6",'IN STORE SALES RECORD'!$D$6:$D$97,'WHS STK MGT & ALLOC.'!$A25) -> 0 | N25: =ROUND(($O25/($H25-($M25+$K25))*100),3) -> 0 | O25: =SUMIFS('IN STORE SALES RECORD'!$E$6:$E$97,'IN STORE SALES RECORD'!$A$6:$A$97, "WEEK 6",'IN STORE SALES RECORD'!$D$6:$D$97,'WHS STK MGT & ALLOC.'!$A25) -> 0 | P25: =ROUND(($Q25/($H25-($M25+$K25+$O25))*100),3) -> 0 | Q25: =SUMIFS('IN STORE SALES RECORD'!$E$6:$E$97,'IN STORE SALES RECORD'!$A$6:$A$97, "WEEK 6",'IN STORE SALES RECORD'!$D$6:$D$97,'WHS STK MGT & ALLOC.'!$A25) -> 0 | R25: =ROUND(($S25/($H25-($M25+$K25+$O25+$Q25))*100),3) -> 0 | S25: =SUMIFS('IN STORE SALES RECORD'!$E$6:$E$97,'IN STORE SALES RECORD'!$A$6:$A$97, "WEEK 6",'IN STORE SALES RECORD'!$D$6:$D$97,'WHS STK MGT & ALLOC.'!$A25) -> 0 | T25: =ROUND(($U25/($H25-($M25+$K25+$O25+$Q25+$S25))*100),3) -> 0 | U25: =SUMIFS('IN STORE SALES RECORD'!$E$6:$E$97,'IN STORE SALES RECORD'!$A$6:$A$97, "WEEK 6",'IN STORE SALES RECORD'!$D$6:$D$97,'WHS STK MGT & ALLOC.'!$A25) -> 0 | V25: =ROUND(($W25/($H25-($M25+$K25+$O25+$Q25+$S25+$U25))*100),3) -> 0 | W25: =SUMIFS('IN STORE SALES RECORD'!$E$6:$E$97,'IN STORE SALES RECORD'!$A$6:$A$97, "WEEK 6",'IN STORE SALES RECORD'!$D$6:$D$97,'WHS STK MGT & ALLOC.'!$A25) -> 0 | X25: =ROUND(($Y25/($H25-($M25+$K25+$O25+$Q25+$S25+$U25+$W25))*100),3) -> 0 | Y25: =SUMIFS('IN STORE SALES RECORD'!$E$6:$E$97,'IN STORE SALES RECORD'!$A$6:$A$97, "WEEK 6",'IN STORE SALES RECORD'!$D$6:$D$97,'WHS STK MGT & ALLOC.'!$A25) -> 0
A26: BO-PA-CO-GR-10 | B26: =IFERROR(INDEX('REFERENCING & DATABASE'!$E$7:$E$131,MATCH($A26,'REFERENCING & DATABASE'!$D$7:$D$131,0)),"") -> Cozy Joggers | C26: =IFERROR(INDEX('REFERENCING & DATABASE'!$B$7:$B$131,MATCH($A26,'REFERENCING & DATABASE'!$D$7:$D$131,0)),"") -> BOTTOMS | D26: =IFERROR(INDEX('REFERENCING & DATABASE'!$C$7:$C$131,MATCH($A26,'REFERENCING & DATABASE'!$D$7:$D$131,0)),"") -> PANTS | E26: =IFERROR(INDEX('REFERENCING & DATABASE'!$F$7:$F$131,MATCH($A26,'REFERENCING & DATABASE'!$D$7:$D$131,0)),"") -> A comfortable and relaxed-fit style for lounging or exercising. | F26: =IFERROR(INDEX('REFERENCING & DATABASE'!$G$7:$G$131,MATCH($A26,'REFERENCING & DATABASE'!$D$7:$D$131,0)),"") -> Grey | G26: =IFERROR(INDEX('REFERENCING & DATABASE'!$H$7:$H$131,MATCH($A26,'REFERENCING & DATABASE'!$D$7:$D$131,0)),"") -> 10 | H26: =IFERROR(INDEX('REFERENCING & DATABASE'!$A$7:$A$131,MATCH($A26,'REFERENCING & DATABASE'!$D$7:$D$131,0)),"") -> 755 | I26: =H26-SUM($K26,$M26,$O26,$Q26) -> 745 | J26: =ROUND((($K26/$H26)*100),3) -> 1.325 | K26: =SUMIFS('IN STORE SALES RECORD'!$E$6:$E$97,'IN STORE SALES RECORD'!$A$6:$A$97, "WEEK 1",'IN STORE SALES RECORD'!$D$6:$D$97,'WHS STK MGT & ALLOC.'!$A26)+10 -> 10 | L26: =ROUND(($M26/($H26-$K26))*100,3) -> 0 | M26: =SUMIFS('IN STORE SALES RECORD'!$E$6:$E$97,'IN STORE SALES RECORD'!$A$6:$A$97, "WEEK 6",'IN STORE SALES RECORD'!$D$6:$D$97,'WHS STK MGT & ALLOC.'!$A26) -> 0 | N26: =ROUND(($O26/($H26-($M26+$K26))*100),3) -> 0 | O26: =SUMIFS('IN STORE SALES RECORD'!$E$6:$E$97,'IN STORE SALES RECORD'!$A$6:$A$97, "WEEK 6",'IN STORE SALES RECORD'!$D$6:$D$97,'WHS STK MGT & ALLOC.'!$A26) -> 0 | P26: =ROUND(($Q26/($H26-($M26+$K26+$O26))*100),3) -> 0 | Q26: =SUMIFS('IN STORE SALES RECORD'!$E$6:$E$97,'IN STORE SALES RECORD'!$A$6:$A$97, "WEEK 6",'IN STORE SALES RECORD'!$D$6:$D$97,'WHS STK MGT & ALLOC.'!$A26) -> 0 | R26: =ROUND(($S26/($H26-($M26+$K26+$O26+$Q26))*100),3) -> 0 | S26: =SUMIFS('IN STORE SALES RECORD'!$E$6:$E$97,'IN STORE SALES RECORD'!$A$6:$A$97, "WEEK 6",'IN STORE SALES RECORD'!$D$6:$D$97,'WHS STK MGT & ALLOC.'!$A26) -> 0 | T26: =ROUND(($U26/($H26-($M26+$K26+$O26+$Q26+$S26))*100),3) -> 0 | U26: =SUMIFS('IN STORE SALES RECORD'!$E$6:$E$97,'IN STORE SALES RECORD'!$A$6:$A$97, "WEEK 6",'IN STORE SALES RECORD'!$D$6:$D$97,'WHS STK MGT & ALLOC.'!$A26) -> 0 | V26: =ROUND(($W26/($H26-($M26+$K26+$O26+$Q26+$S26+$U26))*100),3) -> 0 | W26: =SUMIFS('IN STORE SALES RECORD'!$E$6:$E$97,'IN STORE SALES RECORD'!$A$6:$A$97, "WEEK 6",'IN STORE SALES RECORD'!$D$6:$D$97,'WHS STK MGT & ALLOC.'!$A26) -> 0 | X26: =ROUND(($Y26/($H26-($M26+$K26+$O26+$Q26+$S26+$U26+$W26))*100),3) -> 0 | Y26: =SUMIFS('IN STORE SALES RECORD'!$E$6:$E$97,'IN STORE SALES RECORD'!$A$6:$A$97, "WEEK 6",'IN STORE SALES RECORD'!$D$6:$D$97,'WHS STK MGT & ALLOC.'!$A26) -> 0
